Workbook

Sheet التوقعات
A1: توقع الفوترة لكل حساب: 2026 ونهاية السنة و2027 (المفوتر + المحصل عن سنوات سابقة)
B2: نسبة النمو لسيناريو 2027 (عدّلها هنا): | C2: 0.07
A3: رقم الحساب | B3: اسم الحساب | C3: التبويب | D3: الحالة | E3: 2023 فعلي | F3: 2024 فعلي | G3: 2025 فعلي | H3: 2026 فعلي (حتى سبتمبر) | I3: 2026 توقع نهاية السنة | J3: ="2027 – سيناريو "&TEXT($C$2,"0.0%") | K3: معدل النمو التاريخي (بعد السقف) | L3: 2027 – سيناريو النمو التاريخي | M3: نمو 2024 عن 2023 | N3: نمو 2025 عن 2024 | O3: نمو 2026 توقع عن 2025 | P3: نمو 2027 (سيناريو النمو الثابت) عن 2026 | Q3: نمو 2027 (سيناريو تاريخي) عن 2026 | R3: تنبيه
A4: 1438001 | B4: جزاءات و غرامات مفروضة بموجب أنظمة الجهة | C4: جزاءات وغرامات | D4: نشط | E4: 8.0458745e+08 | F4: 8.4514112e+08 | G4: 9.9551858e+08 | H4: 1.0652001e+09 | I4: =IF(D4="متوقف",0,H4*الافتراضات!$B$4) | J4: =I4*(1+الافتراضات!$B$5) | K4: =IF(D4="متوقف",0,MAX(-الافتراضات!$B$6,MIN(الافتراضات!$B$6,0.112341))) | L4: =I4*(1+K4) | M4: =IF(E4=0,"",F4/E4-1) | N4: =IF(F4=0,"",G4/F4-1) | O4: =IF(G4=0,"",I4/G4-1) | P4: =IF(I4=0,"",J4/I4-1) | Q4: =IF(I4=0,"",L4/I4-1)
A5: 14155 | B5: ريع الأراضي (تأجير الأراض ) | C5: إيرادات إستثمارية | D5: نشط | E5: 9.3602605e+08 | F5: 9.5569964e+08 | G5: 8.276282e+08 | H5: 8.0359943e+08 | I5: =IF(D5="متوقف",0,H5*الافتراضات!$B$4) | J5: =I5*(1+الافتراضات!$B$5) | K5: =IF(D5="متوقف",0,MAX(-الافتراضات!$B$6,MIN(الافتراضات!$B$6,-0.059684))) | L5: =I5*(1+K5) | M5: =IF(E5=0,"",F5/E5-1) | N5: =IF(F5=0,"",G5/F5-1) | O5: =IF(G5=0,"",I5/G5-1) | P5: =IF(I5=0,"",J5/I5-1) | Q5: =IF(I5=0,"",L5/I5-1)
A6: 142113 | B6: ايرادات اللوحات الدعائية | C6: الرسوم والتراخيص | D6: نشط | E6: 1.7506795e+08 | F6: 6.8026832e+08 | G6: 1.0561577e+09 | H6: 1.2647527e+08 | I6: =IF(D6="متوقف",0,H6*الافتراضات!$B$4) | J6: =I6*(1+الافتراضات!$B$5) | K6: =IF(D6="متوقف",0,MAX(-الافتراضات!$B$6,MIN(الافتراضات!$B$6,1.456185))) | L6: =I6*(1+K6) | M6: =IF(E6=0,"",F6/E6-1) | N6: =IF(F6=0,"",G6/F6-1) | O6: =IF(G6=0,"",I6/G6-1) | P6: =IF(I6=0,"",J6/I6-1) | Q6: =IF(I6=0,"",L6/I6-1) | R6: تذبذب عالٍ – راجع التوقع
A7: 11452104 | B7: إصدار رخص الأنشطة التجارية | C7: الرسوم والتراخيص | D7: نشط | E7: 2.8130401e+08 | F7: 3.0902467e+08 | G7: 2.8705589e+08 | H7: 2.6630503e+08 | I7: =IF(D7="متوقف",0,H7*الافتراضات!$B$4) | J7: =I7*(1+الافتراضات!$B$5) | K7: =IF(D7="متوقف",0,MAX(-الافتراضات!$B$6,MIN(الافتراضات!$B$6,0.010172))) | L7: =I7*(1+K7) | M7: =IF(E7=0,"",F7/E7-1) | N7: =IF(F7=0,"",G7/F7-1) | O7: =IF(G7=0,"",I7/G7-1) | P7: =IF(I7=0,"",J7/I7-1) | Q7: =IF(I7=0,"",L7/I7-1)
A8: 11452103 | B8: ايراد اصدار تراخيص المباني والاسوار - أمانة منطقة الرياض | C8: الرسوم والتراخيص | D8: نشط | E8: 2.2867308e+08 | F8: 2.573189e+08 | G8: 3.2186036e+08 | H8: 2.0613124e+08 | I8: =IF(D8="متوقف",0,H8*الافتراضات!$B$4) | J8: =I8*(1+الافتراضات!$B$5) | K8: =IF(D8="متوقف",0,MAX(-الافتراضات!$B$6,MIN(الافتراضات!$B$6,0.186387))) | L8: =I8*(1+K8) | M8: =IF(E8=0,"",F8/E8-1) | N8: =IF(F8=0,"",G8/F8-1) | O8: =IF(G8=0,"",I8/G8-1) | P8: =IF(I8=0,"",J8/I8-1) | Q8: =IF(I8=0,"",L8/I8-1)
A9: 11452512 | B9: ايرادات لوحات المحلات | C9: الرسوم والتراخيص | D9: نشط | E9: 239067590 | F9: 249350690 | G9: 2.1063206e+08 | H9: 1.8772903e+08 | I9: =IF(D9="متوقف",0,H9*الافتراضات!$B$4) | J9: =I9*(1+الافتراضات!$B$5) | K9: =IF(D9="متوقف",0,MAX(-الافتراضات!$B$6,MIN(الافتراضات!$B$6,-0.061354))) | L9: =I9*(1+K9) | M9: =IF(E9=0,"",F9/E9-1) | N9: =IF(F9=0,"",G9/F9-1) | O9: =IF(G9=0,"",I9/G9-1) | P9: =IF(I9=0,"",J9/I9-1) | Q9: =IF(I9=0,"",L9/I9-1)
A10: 11442 | B10: اشغال مرافق الايواء | C10: التبغ والإيواء | D10: نشط | E10: 2.3172993e+08 | F10: 2.7657152e+08 | G10: 2.2103217e+08 | H10: 1.5668295e+08 | I10: =IF(D10="متوقف",0,H10*الافتراضات!$B$4) | J10: =I10*(1+الافتراضات!$B$5) | K10: =IF(D10="متوقف",0,MAX(-الافتراضات!$B$6,MIN(الافتراضات!$B$6,-0.023355))) | L10: =I10*(1+K10) | M10: =IF(E10=0,"",F10/E10-1) | N10: =IF(F10=0,"",G10/F10-1) | O10: =IF(G10=0,"",I10/G10-1) | P10: =IF(I10=0,"",J10/I10-1) | Q10: =IF(I10=0,"",L10/I10-1)
A11: 142162 | B11: إيرادات تأجير المرافق | C11: إيرادات إستثمارية | D11: نشط | E11: 33614411 | F11: 53697028 | G11: 35072726 | H11: 4.307655e+08 | I11: =IF(D11="متوقف",0,H11*الافتراضات!$B$4) | J11: =I11*(1+الافتراضات!$B$5) | K11: =IF(D11="متوقف",0,MAX(-الافتراضات!$B$6,MIN(الافتراضات!$B$6,0.021462))) | L11: =I11*(1+K11) | M11: =IF(E11=0,"",F11/E11-1) | N11: =IF(F11=0,"",G11/F11-1) | O11: =IF(G11=0,"",I11/G11-1) | P11: =IF(I11=0,"",J11/I11-1) | Q11: =IF(I11=0,"",L11/I11-1) | R11: تذبذب عالٍ – راجع التوقع
A12: 1421999 | B12: مبيعات أخرى | C12: أخرى | D12: نشط | E12: 1.5240112e+08 | F12: 1.6674976e+08 | G12: 73660918 | H12: 1.4770066e+08 | I12: =IF(D12="متوقف",0,H12*الافتراضات!$B$4) | J12: =I12*(1+الافتراضات!$B$5) | K12: =IF(D12="متوقف",0,MAX(-الافتراضات!$B$6,MIN(الافتراضات!$B$6,-0.304776))) | L12: =I12*(1+K12) | M12: =IF(E12=0,"",F12/E12-1) | N12: =IF(F12=0,"",G12/F12-1) | O12: =IF(G12=0,"",I12/G12-1) | P12: =IF(I12=0,"",J12/I12-1) | Q12: =IF(I12=0,"",L12/I12-1) | R12: تذبذب عالٍ – راجع التوقع
A13: 144122 | B13: إيرادات متنوعه | C13: أخرى | D13: نشط | E13: 9941900.6 | F13: 14133817 | G13: 80747739 | H13: 3.1649696e+08 | I13: =IF(D13="متوقف",0,H13*الافتراضات!$B$4) | J13: =I13*(1+الافتراضات!$B$5) | K13: =IF(D13="متوقف",0,MAX(-الافتراضات!$B$6,MIN(الافتراضات!$B$6,1.849906))) | L13: =I13*(1+K13) | M13: =IF(E13=0,"",F13/E13-1) | N13: =IF(F13=0,"",G13/F13-1) | O13: =IF(G13=0,"",I13/G13-1) | P13: =IF(I13=0,"",J13/I13-1) | Q13: =IF(I13=0,"",L13/I13-1) | R13: تذبذب عالٍ – راجع التوقع
A14: 1421911 | B14: رسم مبيعات محلات تقديم منتجات التبغ | C14: التبغ والإيواء | D14: نشط | E14: 75066033 | F14: 1.4220277e+08 | G14: 1.0545518e+08 | H14: 80723093 | I14: =IF(D14="متوقف",0,H14*الافتراضات!$B$4) | J14: =I14*(1+الافتراضات!$B$5) | K14: =IF(D14="متوقف",0,MAX(-الافتراضات!$B$6,MIN(الافتراضات!$B$6,0.185256))) | L14: =I14*(1+K14) | M14: =IF(E14=0,"",F14/E14-1) | N14: =IF(F14=0,"",G14/F14-1) | O14: =IF(G14=0,"",I14/G14-1) | P14: =IF(I14=0,"",J14/I14-1) | Q14: =IF(I14=0,"",L14/I14-1)
A15: 1421909 | B15: جمع النفايات | C15: الرسوم والتراخيص | D15: نشط | E15: 83027852 | F15: 89269941 | G15: 80988494 | H15: 79213506 | I15: =IF(D15="متوقف",0,H15*الافتراضات!$B$4) | J15: =I15*(1+الافتراضات!$B$5) | K15: =IF(D15="متوقف",0,MAX(-الافتراضات!$B$6,MIN(الافتراضات!$B$6,-0.012358))) | L15: =I15*(1+K15) | M15: =IF(E15=0,"",F15/E15-1) | N15: =IF(F15=0,"",G15/F15-1) | O15: =IF(G15=0,"",I15/G15-1) | P15: =IF(I15=0,"",J15/I15-1) | Q15: =IF(I15=0,"",L15/I15-1)
A16: 11452105 | B16: رسوم تراخيص حفر الشوارع | C16: الرسوم والتراخيص | D16: نشط | E16: 66884900 | F16: 65467286 | G16: 634736.47 | H16: 1350 | I16: =IF(D16="متوقف",0,H16*الافتراضات!$B$4) | J16: =I16*(1+الافتراضات!$B$5) | K16: =IF(D16="متوقف",0,MAX(-الافتراضات!$B$6,MIN(الافتراضات!$B$6,-0.902583))) | L16: =I16*(1+K16) | M16: =IF(E16=0,"",F16/E16-1) | N16: =IF(F16=0,"",G16/F16-1) | O16: =IF(G16=0,"",I16/G16-1) | P16: =IF(I16=0,"",J16/I16-1) | Q16: =IF(I16=0,"",L16/I16-1)
A17: 11452108 | B17: ايراد اصدار القرارات المساحية - أمانة منطقة الرياض | C17: الرسوم والتراخيص | D17: نشط | E17: 4422269.6 | F17: 19704385 | G17: 26909389 | H17: 34133807 | I17: =IF(D17="متوقف",0,H17*الافتراضات!$B$4) | J17: =I17*(1+الافتراضات!$B$5) | K17: =IF(D17="متوقف",0,MAX(-الافتراضات!$B$6,MIN(الافتراضات!$B$6,1.466774))) | L17: =I17*(1+K17) | M17: =IF(E17=0,"",F17/E17-1) | N17: =IF(F17=0,"",G17/F17-1) | O17: =IF(G17=0,"",I17/G17-1) | P17: =IF(I17=0,"",J17/I17-1) | Q17: =IF(I17=0,"",L17/I17-1)
A18: 1422108 | B18: الشهادات الصحية | C18: الرسوم والتراخيص | D18: نشط | E18: 21268656 | F18: 13869671 | G18: 26299400 | H18: 21634359 | I18: =IF(D18="متوقف",0,H18*الافتراضات!$B$4) | J18: =I18*(1+الافتراضات!$B$5) | K18: =IF(D18="متوقف",0,MAX(-الافتراضات!$B$6,MIN(الافتراضات!$B$6,0.111995))) | L18: =I18*(1+K18) | M18: =IF(E18=0,"",F18/E18-1) | N18: =IF(F18=0,"",G18/F18-1) | O18: =IF(G18=0,"",I18/G18-1) | P18: =IF(I18=0,"",J18/I18-1) | Q18: =IF(I18=0,"",L18/I18-1)
A19: 1422121 | B19: رسم ترخيص نشاط تقديم منتجات التبغ | C19: التبغ والإيواء | D19: نشط | E19: 16987800 | F19: 18210000 | G19: 16212479 | H19: 14308008 | I19: =IF(D19="متوقف",0,H19*الافتراضات!$B$4) | J19: =I19*(1+الافتراضات!$B$5) | K19: =IF(D19="متوقف",0,MAX(-الافتراضات!$B$6,MIN(الافتراضات!$B$6,-0.023086))) | L19: =I19*(1+K19) | M19: =IF(E19=0,"",F19/E19-1) | N19: =IF(F19=0,"",G19/F19-1) | O19: =IF(G19=0,"",I19/G19-1) | P19: =IF(I19=0,"",J19/I19-1) | Q19: =IF(I19=0,"",L19/I19-1)
A20: بدون رقم | B20: بدون رقم (خدمات علم + جزاءات) | C20: علم / جزاءات | D20: نشط | E20: 4860068.8 | F20: 14420134 | G20: 22037760 | H20: 21837838 | I20: =IF(D20="متوقف",0,H20*الافتراضات!$B$4) | J20: =I20*(1+الافتراضات!$B$5) | K20: =IF(D20="متوقف",0,MAX(-الافتراضات!$B$6,MIN(الافتراضات!$B$6,1.129426))) | L20: =I20*(1+K20) | M20: =IF(E20=0,"",F20/E20-1) | N20: =IF(F20=0,"",G20/F20-1) | O20: =IF(G20=0,"",I20/G20-1) | P20: =IF(I20=0,"",J20/I20-1) | Q20: =IF(I20=0,"",L20/I20-1)
A21: 142163 | B21: إيرادات تأجير مباني تجارية | C21: إيرادات إستثمارية | D21: نشط | E21: 9048255.9 | F21: 7544256.2 | G21: 4918746.8 | H21: 12310615 | I21: =IF(D21="متوقف",0,H21*الافتراضات!$B$4) | J21: =I21*(1+الافتراضات!$B$5) | K21: =IF(D21="متوقف",0,MAX(-الافتراضات!$B$6,MIN(الافتراضات!$B$6,-0.262699))) | L21: =I21*(1+K21) | M21: =IF(E21=0,"",F21/E21-1) | N21: =IF(F21=0,"",G21/F21-1) | O21: =IF(G21=0,"",I21/G21-1) | P21: =IF(I21=0,"",J21/I21-1) | Q21: =IF(I21=0,"",L21/I21-1) | R21: تذبذب عالٍ – راجع التوقع
A22: 1422109 | B22: ايرادات الكشفية | C22: الرسوم والتراخيص | D22: نشط | E22: 9597160.1 | F22: 9593369.7 | G22: 7704211.8 | H22: 6331998.5 | I22: =IF(D22="متوقف",0,H22*الافتراضات!$B$4) | J22: =I22*(1+الافتراضات!$B$5) | K22: =IF(D22="متوقف",0,MAX(-الافتراضات!$B$6,MIN(الافتراضات!$B$6,-0.104032))) | L22: =I22*(1+K22) | M22: =IF(E22=0,"",F22/E22-1) | N22: =IF(F22=0,"",G22/F22-1) | O22: =IF(G22=0,"",I22/G22-1) | P22: =IF(I22=0,"",J22/I22-1) | Q22: =IF(I22=0,"",L22/I22-1)
A23: 11452111 | B23: المقابل المالي للسماح للأنشطة التجارية بالعمل (24) ساعة | C23: الرسوم والتراخيص | D23: نشط | E23: 6077736.7 | F23: 5228065.2 | G23: 6051210.2 | H23: 12106223 | I23: =IF(D23="متوقف",0,H23*الافتراضات!$B$4) | J23: =I23*(1+الافتراضات!$B$5) | K23: =IF(D23="متوقف",0,MAX(-الافتراضات!$B$6,MIN(الافتراضات!$B$6,-0.002185))) | L23: =I23*(1+K23) | M23: =IF(E23=0,"",F23/E23-1) | N23: =IF(F23=0,"",G23/F23-1) | O23: =IF(G23=0,"",I23/G23-1) | P23: =IF(I23=0,"",J23/I23-1) | Q23: =IF(I23=0,"",L23/I23-1) | R23: تذبذب عالٍ – راجع التوقع
A24: 1421910 | B24: اصدار تراخيص اشغال الارصفة العامة و الطرق | C24: الرسوم والتراخيص | D24: نشط | E24: 3853581.4 | F24: 2946421.8 | G24: 3566627.4 | H24: 3660790.6 | I24: =IF(D24="متوقف",0,H24*الافتراضات!$B$4) | J24: =I24*(1+الافتراضات!$B$5) | K24: =IF(D24="متوقف",0,MAX(-الافتراضات!$B$6,MIN(الافتراضات!$B$6,-0.037952))) | L24: =I24*(1+K24) | M24: =IF(E24=0,"",F24/E24-1) | N24: =IF(F24=0,"",G24/F24-1) | O24: =IF(G24=0,"",I24/G24-1) | P24: =IF(I24=0,"",J24/I24-1) | Q24: =IF(I24=0,"",L24/I24-1)
A25: 1439 | B25: ايرادات مبيعات ناتجه من النشاط غير مصنفة | C25: جزاءات وغرامات | D25: نشط | E25: 3537100 | F25: 256186 | G25: 8503508 | H25: 519000 | I25: =IF(D25="متوقف",0,H25*الافتراضات!$B$4) | J25: =I25*(1+الافتراضات!$B$5) | K25: =IF(D25="متوقف",0,MAX(-الافتراضات!$B$6,MIN(الافتراضات!$B$6,0.550513))) | L25: =I25*(1+K25) | M25: =IF(E25=0,"",F25/E25-1) | N25: =IF(F25=0,"",G25/F25-1) | O25: =IF(G25=0,"",I25/G25-1) | P25: =IF(I25=0,"",J25/I25-1) | Q25: =IF(I25=0,"",L25/I25-1) | R25: تذبذب عالٍ – راجع التوقع
A26: 1421901 | B26: بيع الوثائق والأنظمة | C26: أخرى | D26: نشط | E26: 2945006 | F26: 2753795 | G26: 2520477 | H26: 1860236 | I26: =IF(D26="متوقف",0,H26*الافتراضات!$B$4) | J26: =I26*(1+الافتراضات!$B$5) | K26: =IF(D26="متوقف",0,MAX(-الافتراضات!$B$6,MIN(الافتراضات!$B$6,-0.074880))) | L26: =I26*(1+K26) | M26: =IF(E26=0,"",F26/E26-1) | N26: =IF(F26=0,"",G26/F26-1) | O26: =IF(G26=0,"",I26/G26-1) | P26: =IF(I26=0,"",J26/I26-1) | Q26: =IF(I26=0,"",L26/I26-1)
A27: 1421903 | B27: مبيعات التيار الكهربائي | C27: إيرادات إستثمارية | D27: نشط | E27: 0 | F27: 0 | G27: 8083209.8 | H27: 302027.65 | I27: =IF(D27="متوقف",0,H27*الافتراضات!$B$4) | J27: =I27*(1+الافتراضات!$B$5) | K27: =IF(D27="متوقف",0,MAX(-الافتراضات!$B$6,MIN(الافتراضات!$B$6,0.000000))) | L27: =I27*(1+K27) | M27: =IF(E27=0,"",F27/E27-1) | N27: =IF(F27=0,"",G27/F27-1) | O27: =IF(G27=0,"",I27/G27-1) | P27: =IF(I27=0,"",J27/I27-1) | Q27: =IF(I27=0,"",L27/I27-1) | R27: تذبذب عالٍ – راجع التوقع
A28: 1438 | B28: جزاءات وغرامات مفروضة بموجب أنظمة الجهة | C28: جزاءات وغرامات | D28: نشط | E28: 6881203 | F28: 486100 | G28: 352900 | H28: 59500 | I28: =IF(D28="متوقف",0,H28*الافتراضات!$B$4) | J28: =I28*(1+الافتراضات!$B$5) | K28: =IF(D28="متوقف",0,MAX(-الافتراضات!$B$6,MIN(الافتراضات!$B$6,-0.773539))) | L28: =I28*(1+K28) | M28: =IF(E28=0,"",F28/E28-1) | N28: =IF(F28=0,"",G28/F28-1) | O28: =IF(G28=0,"",I28/G28-1) | P28: =IF(I28=0,"",J28/I28-1) | Q28: =IF(I28=0,"",L28/I28-1)
A29: 1421912 | B29: تأجير العقارات لأغراض مؤقته | C29: إيرادات إستثمارية | D29: نشط | E29: 838420.19 | F29: 2053263.4 | G29: 2460303.5 | H29: 1447855 | I29: =IF(D29="متوقف",0,H29*الافتراضات!$B$4) | J29: =I29*(1+الافتراضات!$B$5) | K29: =IF(D29="متوقف",0,MAX(-الافتراضات!$B$6,MIN(الافتراضات!$B$6,0.713024))) | L29: =I29*(1+K29) | M29: =IF(E29=0,"",F29/E29-1) | N29: =IF(F29=0,"",G29/F29-1) | O29: =IF(G29=0,"",I29/G29-1) | P29: =IF(I29=0,"",J29/I29-1) | Q29: =IF(I29=0,"",L29/I29-1)
A30: 11452106 | B30: اصدار التراخيص بتأسيس أو تشغيل ابراج الاتصالات | C30: الرسوم والتراخيص | D30: نشط | E30: 1007100 | F30: 1570100 | G30: 1590000 | H30: 476400 | I30: =IF(D30="متوقف",0,H30*الافتراضات!$B$4) | J30: =I30*(1+الافتراضات!$B$5) | K30: =IF(D30="متوقف",0,MAX(-الافتراضات!$B$6,MIN(الافتراضات!$B$6,0.256499))) | L30: =I30*(1+K30) | M30: =IF(E30=0,"",F30/E30-1) | N30: =IF(F30=0,"",G30/F30-1) | O30: =IF(G30=0,"",I30/G30-1) | P30: =IF(I30=0,"",J30/I30-1) | Q30: =IF(I30=0,"",L30/I30-1)
A31: 11452110 | B31: إصدار تراخيص إستخدام أملاك خاصة لإقامة فعاليات | C31: الرسوم والتراخيص | D31: نشط | E31: 975004.05 | F31: 1038789.2 | G31: 1014443.2 | H31: 646845.12 | I31: =IF(D31="متوقف",0,H31*الافتراضات!$B$4) | J31: =I31*(1+الافتراضات!$B$5) | K31: =IF(D31="متوقف",0,MAX(-الافتراضات!$B$6,MIN(الافتراضات!$B$6,0.020025))) | L31: =I31*(1+K31) | M31: =IF(E31=0,"",F31/E31-1) | N31: =IF(F31=0,"",G31/F31-1) | O31: =IF(G31=0,"",I31/G31-1) | P31: =IF(I31=0,"",J31/I31-1) | Q31: =IF(I31=0,"",L31/I31-1)
A32: 141229 | B32: أرباح أخرى | C32: إيرادات إستثمارية | D32: نشط | E32: 1110572 | F32: 2220000 | G32: 30000 | H32: 60000 | I32: =IF(D32="متوقف",0,H32*الافتراضات!$B$4) | J32: =I32*(1+الافتراضات!$B$5) | K32: =IF(D32="متوقف",0,MAX(-الافتراضات!$B$6,MIN(الافتراضات!$B$6,-0.835643))) | L32: =I32*(1+K32) | M32: =IF(E32=0,"",F32/E32-1) | N32: =IF(F32=0,"",G32/F32-1) | O32: =IF(G32=0,"",I32/G32-1) | P32: =IF(I32=0,"",J32/I32-1) | Q32: =IF(I32=0,"",L32/I32-1)
A33: 11452109 | B33: اعتماد مخططات التطوير العقاري | C33: الرسوم والتراخيص | D33: نشط | E33: 1311574.5 | F33: 1330639.2 | G33: 592396.73 | H33: 100 | I33: =IF(D33="متوقف",0,H33*الافتراضات!$B$4) | J33: =I33*(1+الافتراضات!$B$5) | K33: =IF(D33="متوقف",0,MAX(-الافتراضات!$B$6,MIN(الافتراضات!$B$6,-0.327937))) | L33: =I33*(1+K33) | M33: =IF(E33=0,"",F33/E33-1) | N33: =IF(F33=0,"",G33/F33-1) | O33: =IF(G33=0,"",I33/G33-1) | P33: =IF(I33=0,"",J33/I33-1) | Q33: =IF(I33=0,"",L33/I33-1)
A34: 11452107 | B34: اصدار التراخيص بتأسيس أو تشغيل الصراف الآلي | C34: الرسوم والتراخيص | D34: نشط | E34: 54000 | F34: 92000 | G34: 236273.52 | H34: 200184.61 | I34: =IF(D34="متوقف",0,H34*الافتراضات!$B$4) | J34: =I34*(1+الافتراضات!$B$5) | K34: =IF(D34="متوقف",0,MAX(-الافتراضات!$B$6,MIN(الافتراضات!$B$6,1.091754))) | L34: =I34*(1+K34) | M34: =IF(E34=0,"",F34/E34-1) | N34: =IF(F34=0,"",G34/F34-1) | O34: =IF(G34=0,"",I34/G34-1) | P34: =IF(I34=0,"",J34/I34-1) | Q34: =IF(I34=0,"",L34/I34-1)
A35: 3318212 | B35: مرتجع رواتب - فواتير | C35: أخرى | D35: نشط | E35: 0 | F35: 0 | G35: 152767.79 | H35: 361665.23 | I35: =IF(D35="متوقف",0,H35*الافتراضات!$B$4) | J35: =I35*(1+الافتراضات!$B$5) | K35: =IF(D35="متوقف",0,MAX(-الافتراضات!$B$6,MIN(الافتراضات!$B$6,0.000000))) | L35: =I35*(1+K35) | M35: =IF(E35=0,"",F35/E35-1) | N35: =IF(F35=0,"",G35/F35-1) | O35: =IF(G35=0,"",I35/G35-1) | P35: =IF(I35=0,"",J35/I35-1) | Q35: =IF(I35=0,"",L35/I35-1)
A36: 11422 | B36: رسوم منتجات التبغ | C36: التبغ والإيواء | D36: متوقف | E36: 27000 | F36: 5167 | G36: 72000 | H36: 0 | I36: =IF(D36="متوقف",0,H36*الافتراضات!$B$4) | J36: =I36*(1+الافتراضات!$B$5) | K36: =IF(D36="متوقف",0,MAX(-الافتراضات!$B$6,MIN(الافتراضات!$B$6,0.632993))) | L36: =I36*(1+K36) | M36: =IF(E36=0,"",F36/E36-1) | N36: =IF(F36=0,"",G36/F36-1) | O36: =IF(G36=0,"",I36/G36-1) | P36: =IF(I36=0,"",J36/I36-1) | Q36: =IF(I36=0,"",L36/I36-1) | R36: متوقف في 2026 – توقعه صفر
A37: 1422103 | B37: تراخيص المحلات | C37: إيرادات إستثمارية | D37: نشط | E37: 67711.6 | F37: 16269.6 | G37: 1603.2 | H37: 432 | I37: =IF(D37="متوقف",0,H37*الافتراضات!$B$4) | J37: =I37*(1+الافتراضات!$B$5) | K37: =IF(D37="متوقف",0,MAX(-الافتراضات!$B$6,MIN(الافتراضات!$B$6,-0.846127))) | L37: =I37*(1+K37) | M37: =IF(E37=0,"",F37/E37-1) | N37: =IF(F37=0,"",G37/F37-1) | O37: =IF(G37=0,"",I37/G37-1) | P37: =IF(I37=0,"",J37/I37-1) | Q37: =IF(I37=0,"",L37/I37-1)
A38: 11452513 | B38: لوحات إرشـادية | C38: الرسوم والتراخيص | D38: نشط | E38: 55525 | F38: 12875 | G38: 9000 | H38: 600 | I38: =IF(D38="متوقف",0,H38*الافتراضات!$B$4) | J38: =I38*(1+الافتراضات!$B$5) | K38: =IF(D38="متوقف",0,MAX(-الافتراضات!$B$6,MIN(الافتراضات!$B$6,-0.597397))) | L38: =I38*(1+K38) | M38: =IF(E38=0,"",F38/E38-1) | N38: =IF(F38=0,"",G38/F38-1) | O38: =IF(G38=0,"",I38/G38-1) | P38: =IF(I38=0,"",J38/I38-1) | Q38: =IF(I38=0,"",L38/I38-1)
A39: 1421907 | B39: إيرادات المخططات | C39: الرسوم والتراخيص | D39: نشط | E39: 0 | F39: 0 | G39: 21950 | H39: 6350 | I39: =IF(D39="متوقف",0,H39*الافتراضات!$B$4) | J39: =I39*(1+الافتراضات!$B$5) | K39: =IF(D39="متوقف",0,MAX(-الافتراضات!$B$6,MIN(الافتراضات!$B$6,0.000000))) | L39: =I39*(1+K39) | M39: =IF(E39=0,"",F39/E39-1) | N39: =IF(F39=0,"",G39/F39-1) | O39: =IF(G39=0,"",I39/G39-1) | P39: =IF(I39=0,"",J39/I39-1) | Q39: =IF(I39=0,"",L39/I39-1)
A40: 1421908 | B40: ايرادات رسوم خدمات بلدية | C40: إيرادات إستثمارية | D40: متوقف | E40: 16385 | F40: 0 | G40: 0 | H40: 0 | I40: =IF(D40="متوقف",0,H40*الافتراضات!$B$4) | J40: =I40*(1+الافتراضات!$B$5) | K40: =IF(D40="متوقف",0,MAX(-الافتراضات!$B$6,MIN(الافتراضات!$B$6,0.000000))) | L40: =I40*(1+K40) | M40: =IF(E40=0,"",F40/E40-1) | N40: =IF(F40=0,"",G40/F40-1) | O40: =IF(G40=0,"",I40/G40-1) | P40: =IF(I40=0,"",J40/I40-1) | Q40: =IF(I40=0,"",L40/I40-1) | R40: متوقف في 2026 – توقعه صفر
...

Sheet حسب التبويب
A1: ملخص حسب التبويب
A3: التبويب | B3: 2023 فعلي | C3: 2024 فعلي | D3: 2025 فعلي | E3: 2026 فعلي (حتى سبتمبر) | F3: 2026 توقع | G3: 2027 – سيناريو النمو الثابت | H3: 2027 – تاريخي
A4: الرسوم والتراخيص | B4: =SUMIF(التوقعات!$C$4:$C$41,$A4,التوقعات!E$4:E$41) | C4: =SUMIF(التوقعات!$C$4:$C$41,$A4,التوقعات!F$4:F$41) | D4: =SUMIF(التوقعات!$C$4:$C$41,$A4,التوقعات!G$4:G$41) | E4: =SUMIF(التوقعات!$C$4:$C$41,$A4,التوقعات!H$4:H$41) | F4: =SUMIF(التوقعات!$C$4:$C$41,$A4,التوقعات!I$4:I$41) | G4: =SUMIF(التوقعات!$C$4:$C$41,$A4,التوقعات!J$4:J$41) | H4: =SUMIF(التوقعات!$C$4:$C$41,$A4,التوقعات!L$4:L$41)
A5: إيرادات إستثمارية | B5: =SUMIF(التوقعات!$C$4:$C$41,$A5,التوقعات!E$4:E$41) | C5: =SUMIF(التوقعات!$C$4:$C$41,$A5,التوقعات!F$4:F$41) | D5: =SUMIF(التوقعات!$C$4:$C$41,$A5,التوقعات!G$4:G$41) | E5: =SUMIF(التوقعات!$C$4:$C$41,$A5,التوقعات!H$4:H$41) | F5: =SUMIF(التوقعات!$C$4:$C$41,$A5,التوقعات!I$4:I$41) | G5: =SUMIF(التوقعات!$C$4:$C$41,$A5,التوقعات!J$4:J$41) | H5: =SUMIF(التوقعات!$C$4:$C$41,$A5,التوقعات!L$4:L$41)
A6: جزاءات وغرامات | B6: =SUMIF(التوقعات!$C$4:$C$41,$A6,التوقعات!E$4:E$41) | C6: =SUMIF(التوقعات!$C$4:$C$41,$A6,التوقعات!F$4:F$41) | D6: =SUMIF(التوقعات!$C$4:$C$41,$A6,التوقعات!G$4:G$41) | E6: =SUMIF(التوقعات!$C$4:$C$41,$A6,التوقعات!H$4:H$41) | F6: =SUMIF(التوقعات!$C$4:$C$41,$A6,التوقعات!I$4:I$41) | G6: =SUMIF(التوقعات!$C$4:$C$41,$A6,التوقعات!J$4:J$41) | H6: =SUMIF(التوقعات!$C$4:$C$41,$A6,التوقعات!L$4:L$41)
A7: التبغ والإيواء | B7: =SUMIF(التوقعات!$C$4:$C$41,$A7,التوقعات!E$4:E$41) | C7: =SUMIF(التوقعات!$C$4:$C$41,$A7,التوقعات!F$4:F$41) | D7: =SUMIF(التوقعات!$C$4:$C$41,$A7,التوقعات!G$4:G$41) | E7: =SUMIF(التوقعات!$C$4:$C$41,$A7,التوقعات!H$4:H$41) | F7: =SUMIF(التوقعات!$C$4:$C$41,$A7,التوقعات!I$4:I$41) | G7: =SUMIF(التوقعات!$C$4:$C$41,$A7,التوقعات!J$4:J$41) | H7: =SUMIF(التوقعات!$C$4:$C$41,$A7,التوقعات!L$4:L$41)
A8: أخرى | B8: =SUMIF(التوقعات!$C$4:$C$41,$A8,التوقعات!E$4:E$41) | C8: =SUMIF(التوقعات!$C$4:$C$41,$A8,التوقعات!F$4:F$41) | D8: =SUMIF(التوقعات!$C$4:$C$41,$A8,التوقعات!G$4:G$41) | E8: =SUMIF(التوقعات!$C$4:$C$41,$A8,التوقعات!H$4:H$41) | F8: =SUMIF(التوقعات!$C$4:$C$41,$A8,التوقعات!I$4:I$41) | G8: =SUMIF(التوقعات!$C$4:$C$41,$A8,التوقعات!J$4:J$41) | H8: =SUMIF(التوقعات!$C$4:$C$41,$A8,التوقعات!L$4:L$41)
A9: علم / جزاءات | B9: =SUMIF(التوقعات!$C$4:$C$41,$A9,التوقعات!E$4:E$41) | C9: =SUMIF(التوقعات!$C$4:$C$41,$A9,التوقعات!F$4:F$41) | D9: =SUMIF(التوقعات!$C$4:$C$41,$A9,التوقعات!G$4:G$41) | E9: =SUMIF(التوقعات!$C$4:$C$41,$A9,التوقعات!H$4:H$41) | F9: =SUMIF(التوقعات!$C$4:$C$41,$A9,التوقعات!I$4:I$41) | G9: =SUMIF(التوقعات!$C$4:$C$41,$A9,التوقعات!J$4:J$41) | H9: =SUMIF(التوقعات!$C$4:$C$41,$A9,التوقعات!L$4:L$41)
A10: الإجمالي | B10: =SUM(B4:B9) | C10: =SUM(C4:C9) | D10: =SUM(D4:D9) | E10: =SUM(E4:E9) | F10: =SUM(F4:F9) | G10: =SUM(G4:G9) | H10: =SUM(H4:H9)

Sheet تفصيل المكونات
A1: تفصيل: المفوتر مقابل المحصل عن سنوات سابقة (فعلي)
A3: رقم الحساب | B3: اسم الحساب | C3: 2023 مفوتر | D3: 2024 مفوتر | E3: 2025 مفوتر | F3: 2026 مفوتر | G3: 2023 محصل سنوات سابقة | H3: 2024 محصل سنوات سابقة | I3: 2025 محصل سنوات سابقة | J3: 2026 محصل سنوات سابقة
A4: 1438001 | B4: جزاءات و غرامات مفروضة بموجب أنظمة الجهة | C4: 6.852768e+08 | D4: 7.4746877e+08 | E4: 9.1136782e+08 | F4: 8.9914724e+08 | G4: 1.1931065e+08 | H4: 97672356 | I4: 84150751 | J4: 1.6605282e+08
A5: 14155 | B5: ريع الأراضي (تأجير الأراض ) | C5: 8.424131e+08 | D5: 8.1886315e+08 | E5: 6.9982249e+08 | F5: 6.4419498e+08 | G5: 93612948 | H5: 1.3683649e+08 | I5: 1.2780571e+08 | J5: 1.5940445e+08
A6: 142113 | B6: ايرادات اللوحات الدعائية | C6: 1.6929773e+08 | D6: 6.7574553e+08 | E6: 1.0269014e+09 | F6: 89273830 | G6: 5770224.2 | H6: 4522788.8 | I6: 29256350 | J6: 37201440
A7: 11452104 | B7: إصدار رخص الأنشطة التجارية | C7: 2.7656803e+08 | D7: 3.0408275e+08 | E7: 2.8087517e+08 | F7: 2.5881322e+08 | G7: 4735981.6 | H7: 4941912.9 | I7: 6180715.4 | J7: 7491807
A8: 11452103 | B8: ايراد اصدار تراخيص المباني والاسوار - أمانة منطقة الرياض | C8: 2.2716555e+08 | D8: 2.5405622e+08 | E8: 3.091889e+08 | F8: 2.0395432e+08 | G8: 1507527.8 | H8: 3262677.3 | I8: 12671461 | J8: 2176918.6
A9: 11452512 | B9: ايرادات لوحات المحلات | C9: 235334700 | D9: 245643640 | E9: 2.0610851e+08 | F9: 1.8188669e+08 | G9: 3732890 | H9: 3707050 | I9: 4523545 | J9: 5842344.2
A10: 11442 | B10: اشغال مرافق الايواء | C10: 2.2625523e+08 | D10: 2.6578226e+08 | E10: 2.1438879e+08 | F10: 1.5005305e+08 | G10: 5474695.3 | H10: 10789260 | I10: 6643371.4 | J10: 6629902
A11: 142162 | B11: إيرادات تأجير المرافق | C11: 33200366 | D11: 49511131 | E11: 30887736 | F11: 4.2149452e+08 | G11: 414045 | H11: 4185896.7 | I11: 4184990.8 | J11: 9270986.3
A12: 1421999 | B12: مبيعات أخرى | C12: 1.3974671e+08 | D12: 1.2694317e+08 | E12: 57649813 | F12: 1.4517947e+08 | G12: 12654406 | H12: 39806593 | I12: 16011105 | J12: 2521182.4
A13: 144122 | B13: إيرادات متنوعه | C13: 9219073.5 | D13: 13582347 | E13: 78828801 | F13: 2.9719148e+08 | G13: 722827.09 | H13: 551469.75 | I13: 1918938.7 | J13: 19305485
A14: 1421911 | B14: رسم مبيعات محلات تقديم منتجات التبغ | C14: 72701818 | D14: 1.4051366e+08 | E14: 1.0128757e+08 | F14: 78309015 | G14: 2364215.5 | H14: 1689112.2 | I14: 4167606.5 | J14: 2414078
A15: 1421909 | B15: جمع النفايات | C15: 81156665 | D15: 87441840 | E15: 79209686 | F15: 76301331 | G15: 1871186.4 | H15: 1828100.9 | I15: 1778808.3 | J15: 2912175.5
... A41: 142161 | B41: تاجير مباني سكنية | C41: 0 | D41: 0 | E41: 0 | F41: 0 | G41: 0 | H41: 0 | I41: 6000 | J41: 0
B42: الإجمالي | C42: =SUM(C4:C41) | D42: =SUM(D4:D41) | E42: =SUM(E4:E41) | F42: =SUM(F4:F41) | G42: =SUM(G4:G41) | H42: =SUM(H4:H41) | I42: =SUM(I4:I41) | J42: =SUM(J4:J41)

Sheet توقع المحصل 2026
A1: توقع إقفال 2026 كمحصّل فعلي (مسدد عن السنة + محصل سنوات سابقة)
A2: توقع 2026 = المحصل الفعلي حتى سبتمبر × معامل الافتراضات (12÷9). الحسابات المتوقفة في 2026 (لا فوترة ولا تحصيل) توقعها صفر. الضريبة مستبعدة.
A3: رقم الحساب | B3: اسم الحساب | C3: التبويب | D3: الحالة | E3: 2023 محصّل | F3: 2024 محصّل | G3: 2025 محصّل | H3: 2026 محصّل حتى سبتمبر | I3: منه: مسدد عن 2026 | J3: منه: محصل سنوات سابقة | K3: 2026 توقع إقفال (محصّل) | L3: نمو التوقع عن 2025 | M3: توقع الفوترة 2026 | N3: نسبة المحصّل إلى المفوتر (توقع)
A4: 1438001 | B4: جزاءات و غرامات مفروضة بموجب أنظمة الجهة | C4: جزاءات وغرامات | D4: =IF(AND(1065200061.32=0,370612328.79=0),"متوقف","نشط") | E4: 4.5989161e+08 | F4: 3.0358569e+08 | G4: 3.080122e+08 | H4: 3.7061233e+08 | I4: 2.0455951e+08 | J4: 1.6605282e+08 | K4: =IF(D4="متوقف",0,H4*الافتراضات!$B$4) | L4: =IF(G4=0,"",K4/G4-1) | M4: =IFERROR(VLOOKUP(A4,التوقعات!$A$4:$I$41,9,FALSE),0) | N4: =IF(M4=0,"",K4/M4)
A5: 14155 | B5: ريع الأراضي (تأجير الأراض ) | C5: إيرادات إستثمارية | D5: =IF(AND(803599432.03=0,612889120.88=0),"متوقف","نشط") | E5: 7.7918691e+08 | F5: 8.0332346e+08 | G5: 6.4933179e+08 | H5: 6.1288912e+08 | I5: 4.5348467e+08 | J5: 1.5940445e+08 | K5: =IF(D5="متوقف",0,H5*الافتراضات!$B$4) | L5: =IF(G5=0,"",K5/G5-1) | M5: =IFERROR(VLOOKUP(A5,التوقعات!$A$4:$I$41,9,FALSE),0) | N5: =IF(M5=0,"",K5/M5)
A6: 142113 | B6: ايرادات اللوحات الدعائية | C6: الرسوم والتراخيص | D6: =IF(AND(126475270.21=0,122031767.73=0),"متوقف","نشط") | E6: 1.5794654e+08 | F6: 6.095237e+08 | G6: 1.0358998e+08 | H6: 1.2203177e+08 | I6: 84830328 | J6: 37201440 | K6: =IF(D6="متوقف",0,H6*الافتراضات!$B$4) | L6: =IF(G6=0,"",K6/G6-1) | M6: =IFERROR(VLOOKUP(A6,التوقعات!$A$4:$I$41,9,FALSE),0) | N6: =IF(M6=0,"",K6/M6)
A7: 11452104 | B7: إصدار رخص الأنشطة التجارية | C7: الرسوم والتراخيص | D7: =IF(AND(266305026.42=0,250375647.47=0),"متوقف","نشط") | E7: 2.6066749e+08 | F7: 2.7627591e+08 | G7: 2.6749628e+08 | H7: 2.5037565e+08 | I7: 2.4288384e+08 | J7: 7491807 | K7: =IF(D7="متوقف",0,H7*الافتراضات!$B$4) | L7: =IF(G7=0,"",K7/G7-1) | M7: =IFERROR(VLOOKUP(A7,التوقعات!$A$4:$I$41,9,FALSE),0) | N7: =IF(M7=0,"",K7/M7)
A8: 11452103 | B8: ايراد اصدار تراخيص المباني والاسوار - أمانة منطقة الرياض | C8: الرسوم والتراخيص | D8: =IF(AND(206131241.55=0,204002823.21=0),"متوقف","نشط") | E8: 2.2493965e+08 | F8: 2.4458249e+08 | G8: 3.1967527e+08 | H8: 2.0400282e+08 | I8: 2.018259e+08 | J8: 2176918.6 | K8: =IF(D8="متوقف",0,H8*الافتراضات!$B$4) | L8: =IF(G8=0,"",K8/G8-1) | M8: =IFERROR(VLOOKUP(A8,التوقعات!$A$4:$I$41,9,FALSE),0) | N8: =IF(M8=0,"",K8/M8)
A9: 11452512 | B9: ايرادات لوحات المحلات | C9: الرسوم والتراخيص | D9: =IF(AND(187729029.22=0,174294501.5=0),"متوقف","نشط") | E9: 218503365 | F9: 219218740 | G9: 1.9383078e+08 | H9: 1.742945e+08 | I9: 1.6845216e+08 | J9: 5842344.2 | K9: =IF(D9="متوقف",0,H9*الافتراضات!$B$4) | L9: =IF(G9=0,"",K9/G9-1) | M9: =IFERROR(VLOOKUP(A9,التوقعات!$A$4:$I$41,9,FALSE),0) | N9: =IF(M9=0,"",K9/M9)
A10: 11442 | B10: اشغال مرافق الايواء | C10: التبغ والإيواء | D10: =IF(AND(156682947.06=0,136639761.84=0),"متوقف","نشط") | E10: 2.1990586e+08 | F10: 2.567268e+08 | G10: 1.9914967e+08 | H10: 1.3663976e+08 | I10: 1.3000986e+08 | J10: 6629902 | K10: =IF(D10="متوقف",0,H10*الافتراضات!$B$4) | L10: =IF(G10=0,"",K10/G10-1) | M10: =IFERROR(VLOOKUP(A10,التوقعات!$A$4:$I$41,9,FALSE),0) | N10: =IF(M10=0,"",K10/M10)
A11: 142162 | B11: إيرادات تأجير المرافق | C11: إيرادات إستثمارية | D11: =IF(AND(430765503.41=0,428460046.0=0),"متوقف","نشط") | E11: 29573714 | F11: 45452213 | G11: 9.3888968e+08 | H11: 428460046 | I11: 4.1918906e+08 | J11: 9270986.3 | K11: =IF(D11="متوقف",0,H11*الافتراضات!$B$4) | L11: =IF(G11=0,"",K11/G11-1) | M11: =IFERROR(VLOOKUP(A11,التوقعات!$A$4:$I$41,9,FALSE),0) | N11: =IF(M11=0,"",K11/M11)
A12: 1421999 | B12: مبيعات أخرى | C12: أخرى | D12: =IF(AND(147700656.12=0,134076434.91=0),"متوقف","نشط") | E12: 1.105423e+08 | F12: 1.0659308e+08 | G12: 60096374 | H12: 1.3407643e+08 | I12: 1.3155525e+08 | J12: 2521182.4 | K12: =IF(D12="متوقف",0,H12*الافتراضات!$B$4) | L12: =IF(G12=0,"",K12/G12-1) | M12: =IFERROR(VLOOKUP(A12,التوقعات!$A$4:$I$41,9,FALSE),0) | N12: =IF(M12=0,"",K12/M12)
A13: 144122 | B13: إيرادات متنوعه | C13: أخرى | D13: =IF(AND(316496963.26=0,20815752.14=0),"متوقف","نشط") | E13: 8992324 | F13: 8297789.8 | G13: 2477531.4 | H13: 20815752 | I13: 1510267.4 | J13: 19305485 | K13: =IF(D13="متوقف",0,H13*الافتراضات!$B$4) | L13: =IF(G13=0,"",K13/G13-1) | M13: =IFERROR(VLOOKUP(A13,التوقعات!$A$4:$I$41,9,FALSE),0) | N13: =IF(M13=0,"",K13/M13)
A14: 1421911 | B14: رسم مبيعات محلات تقديم منتجات التبغ | C14: التبغ والإيواء | D14: =IF(AND(80723092.94=0,56671709.72=0),"متوقف","نشط") | E14: 65864668 | F14: 79278365 | G14: 67630101 | H14: 56671710 | I14: 54257632 | J14: 2414078 | K14: =IF(D14="متوقف",0,H14*الافتراضات!$B$4) | L14: =IF(G14=0,"",K14/G14-1) | M14: =IFERROR(VLOOKUP(A14,التوقعات!$A$4:$I$41,9,FALSE),0) | N14: =IF(M14=0,"",K14/M14)
A15: 1421909 | B15: جمع النفايات | C15: الرسوم والتراخيص | D15: =IF(AND(79213506.2=0,72223518.14=0),"متوقف","نشط") | E15: 72026385 | F15: 76106717 | G15: 72842924 | H15: 72223518 | I15: 69311343 | J15: 2912175.5 | K15: =IF(D15="متوقف",0,H15*الافتراضات!$B$4) | L15: =IF(G15=0,"",K15/G15-1) | M15: =IFERROR(VLOOKUP(A15,التوقعات!$A$4:$I$41,9,FALSE),0) | N15: =IF(M15=0,"",K15/M15)
A16: 11452105 | B16: رسوم تراخيص حفر الشوارع | C16: الرسوم والتراخيص | D16: =IF(AND(1350.0=0,1350.0=0),"متوقف","نشط") | E16: 66558861 | F16: 65200591 | G16: 590915.43 | H16: 1350 | I16: 0 | J16: 1350 | K16: =IF(D16="متوقف",0,H16*الافتراضات!$B$4) | L16: =IF(G16=0,"",K16/G16-1) | M16: =IFERROR(VLOOKUP(A16,التوقعات!$A$4:$I$41,9,FALSE),0) | N16: =IF(M16=0,"",K16/M16)
A17: 11452108 | B17: ايراد اصدار القرارات المساحية - أمانة منطقة الرياض | C17: الرسوم والتراخيص | D17: =IF(AND(34133807.25=0,31178848.2=0),"متوقف","نشط") | E17: 4316211.9 | F17: 19339698 | G17: 24531494 | H17: 31178848 | I17: 28852796 | J17: 2326052.1 | K17: =IF(D17="متوقف",0,H17*الافتراضات!$B$4) | L17: =IF(G17=0,"",K17/G17-1) | M17: =IFERROR(VLOOKUP(A17,التوقعات!$A$4:$I$41,9,FALSE),0) | N17: =IF(M17=0,"",K17/M17)
A18: 1422108 | B18: الشهادات الصحية | C18: الرسوم والتراخيص | D18: =IF(AND(21634358.52=0,17601110.76=0),"متوقف","نشط") | E18: 20767064 | F18: 12367179 | G18: 26098550 | H18: 17601111 | I18: 17398801 | J18: 202309.67 | K18: =IF(D18="متوقف",0,H18*الافتراضات!$B$4) | L18: =IF(G18=0,"",K18/G18-1) | M18: =IFERROR(VLOOKUP(A18,التوقعات!$A$4:$I$41,9,FALSE),0) | N18: =IF(M18=0,"",K18/M18)
A19: 1422121 | B19: رسم ترخيص نشاط تقديم منتجات التبغ | C19: التبغ والإيواء | D19: =IF(AND(14308008.01=0,13896650.67=0),"متوقف","نشط") | E19: 13322800 | F19: 17925000 | G19: 15681461 | H19: 13896651 | I19: 13332736 | J19: 563914.51 | K19: =IF(D19="متوقف",0,H19*الافتراضات!$B$4) | L19: =IF(G19=0,"",K19/G19-1) | M19: =IFERROR(VLOOKUP(A19,التوقعات!$A$4:$I$41,9,FALSE),0) | N19: =IF(M19=0,"",K19/M19)
A20: بدون رقم | B20: بدون رقم (خدمات علم + جزاءات) | C20: علم / جزاءات | D20: =IF(AND(21837837.5=0,2122923.75=0),"متوقف","نشط") | E20: 4815218.8 | F20: 14256546 | G20: 21814890 | H20: 2122923.8 | I20: 1899660 | J20: 223263.75 | K20: =IF(D20="متوقف",0,H20*الافتراضات!$B$4) | L20: =IF(G20=0,"",K20/G20-1) | M20: =IFERROR(VLOOKUP(A20,التوقعات!$A$4:$I$41,9,FALSE),0) | N20: =IF(M20=0,"",K20/M20)
A21: 142163 | B21: إيرادات تأجير مباني تجارية | C21: إيرادات إستثمارية | D21: =IF(AND(12310614.76=0,10169478.26=0),"متوقف","نشط") | E21: 6866663.4 | F21: 6179302.5 | G21: 3001651.8 | H21: 10169478 | I21: 6947112.5 | J21: 3222365.7 | K21: =IF(D21="متوقف",0,H21*الافتراضات!$B$4) | L21: =IF(G21=0,"",K21/G21-1) | M21: =IFERROR(VLOOKUP(A21,التوقعات!$A$4:$I$41,9,FALSE),0) | N21: =IF(M21=0,"",K21/M21)
A22: 1422109 | B22: ايرادات الكشفية | C22: الرسوم والتراخيص | D22: =IF(AND(6331998.45=0,5723153.45=0),"متوقف","نشط") | E22: 9211384.8 | F22: 8995823.2 | G22: 7132142.9 | H22: 5723153.5 | I22: 5563946.6 | J22: 159206.88 | K22: =IF(D22="متوقف",0,H22*الافتراضات!$B$4) | L22: =IF(G22=0,"",K22/G22-1) | M22: =IFERROR(VLOOKUP(A22,التوقعات!$A$4:$I$41,9,FALSE),0) | N22: =IF(M22=0,"",K22/M22)
A23: 11452111 | B23: المقابل المالي للسماح للأنشطة التجارية بالعمل (24) ساعة | C23: الرسوم والتراخيص | D23: =IF(AND(12106223.42=0,11409758.77=0),"متوقف","نشط") | E23: 6031956.1 | F23: 5166690.6 | G23: 5751371.8 | H23: 11409759 | I23: 11142485 | J23: 267274.16 | K23: =IF(D23="متوقف",0,H23*الافتراضات!$B$4) | L23: =IF(G23=0,"",K23/G23-1) | M23: =IFERROR(VLOOKUP(A23,التوقعات!$A$4:$I$41,9,FALSE),0) | N23: =IF(M23=0,"",K23/M23)
A24: 1421910 | B24: اصدار تراخيص اشغال الارصفة العامة و الطرق | C24: الرسوم والتراخيص | D24: =IF(AND(3660790.62=0,3564931.07=0),"متوقف","نشط") | E24: 3828676.6 | F24: 2909412.6 | G24: 3477675.2 | H24: 3564931.1 | I24: 3475978.8 | J24: 88952.23 | K24: =IF(D24="متوقف",0,H24*الافتراضات!$B$4) | L24: =IF(G24=0,"",K24/G24-1) | M24: =IFERROR(VLOOKUP(A24,التوقعات!$A$4:$I$41,9,FALSE),0) | N24: =IF(M24=0,"",K24/M24)
A25: 1439 | B25: ايرادات مبيعات ناتجه من النشاط غير مصنفة | C25: جزاءات وغرامات | D25: =IF(AND(519000.0=0,183000.0=0),"متوقف","نشط") | E25: 3537100 | F25: 227000 | G25: 8503508 | H25: 183000 | I25: 183000 | J25: 0 | K25: =IF(D25="متوقف",0,H25*الافتراضات!$B$4) | L25: =IF(G25=0,"",K25/G25-1) | M25: =IFERROR(VLOOKUP(A25,التوقعات!$A$4:$I$41,9,FALSE),0) | N25: =IF(M25=0,"",K25/M25)
A26: 1421901 | B26: بيع الوثائق والأنظمة | C26: أخرى | D26: =IF(AND(1860236.0=0,1624137.0=0),"متوقف","نشط") | E26: 2928906 | F26: 2736595 | G26: 2512377 | H26: 1624137 | I26: 1616037 | J26: 8100 | K26: =IF(D26="متوقف",0,H26*الافتراضات!$B$4) | L26: =IF(G26=0,"",K26/G26-1) | M26: =IFERROR(VLOOKUP(A26,التوقعات!$A$4:$I$41,9,FALSE),0) | N26: =IF(M26=0,"",K26/M26)
A27: 1421903 | B27: مبيعات التيار الكهربائي | C27: إيرادات إستثمارية | D27: =IF(AND(302027.65=0,274868.65=0),"متوقف","نشط") | E27: 0 | F27: 0 | G27: 1464687.1 | H27: 274868.65 | I27: 143551.39 | J27: 131317.26 | K27: =IF(D27="متوقف",0,H27*الافتراضات!$B$4) | L27: =IF(G27=0,"",K27/G27-1) | M27: =IFERROR(VLOOKUP(A27,التوقعات!$A$4:$I$41,9,FALSE),0) | N27: =IF(M27=0,"",K27/M27)
A28: 1438 | B28: جزاءات وغرامات مفروضة بموجب أنظمة الجهة | C28: جزاءات وغرامات | D28: =IF(AND(59500.0=0,59500.0=0),"متوقف","نشط") | E28: 4544553 | F28: 486100 | G28: 352900 | H28: 59500 | I28: 0 | J28: 59500 | K28: =IF(D28="متوقف",0,H28*الافتراضات!$B$4) | L28: =IF(G28=0,"",K28/G28-1) | M28: =IFERROR(VLOOKUP(A28,التوقعات!$A$4:$I$41,9,FALSE),0) | N28: =IF(M28=0,"",K28/M28)
A29: 1421912 | B29: تأجير العقارات لأغراض مؤقته | C29: إيرادات إستثمارية | D29: =IF(AND(1447854.96=0,1357611.55=0),"متوقف","نشط") | E29: 838420.19 | F29: 2043840.5 | G29: 2454143.5 | H29: 1357611.6 | I29: 1354461.6 | J29: 3150 | K29: =IF(D29="متوقف",0,H29*الافتراضات!$B$4) | L29: =IF(G29=0,"",K29/G29-1) | M29: =IFERROR(VLOOKUP(A29,التوقعات!$A$4:$I$41,9,FALSE),0) | N29: =IF(M29=0,"",K29/M29)
A30: 11452106 | B30: اصدار التراخيص بتأسيس أو تشغيل ابراج الاتصالات | C30: الرسوم والتراخيص | D30: =IF(AND(476400.0=0,342700.0=0),"متوقف","نشط") | E30: 845300 | F30: 1408700 | G30: 1275300 | H30: 342700 | I30: 189300 | J30: 153400 | K30: =IF(D30="متوقف",0,H30*الافتراضات!$B$4) | L30: =IF(G30=0,"",K30/G30-1) | M30: =IFERROR(VLOOKUP(A30,التوقعات!$A$4:$I$41,9,FALSE),0) | N30: =IF(M30=0,"",K30/M30)
A31: 11452110 | B31: إصدار تراخيص إستخدام أملاك خاصة لإقامة فعاليات | C31: الرسوم والتراخيص | D31: =IF(AND(646845.12=0,594187.77=0),"متوقف","نشط") | E31: 609446.45 | F31: 1038687.2 | G31: 809215.9 | H31: 594187.77 | I31: 579245.45 | J31: 14942.32 | K31: =IF(D31="متوقف",0,H31*الافتراضات!$B$4) | L31: =IF(G31=0,"",K31/G31-1) | M31: =IFERROR(VLOOKUP(A31,التوقعات!$A$4:$I$41,9,FALSE),0) | N31: =IF(M31=0,"",K31/M31)
A32: 141229 | B32: أرباح أخرى | C32: إيرادات إستثمارية | D32: =IF(AND(60000.0=0,60000.0=0),"متوقف","نشط") | E32: 910572 | F32: 2120000 | G32: 30000 | H32: 60000 | I32: 0 | J32: 60000 | K32: =IF(D32="متوقف",0,H32*الافتراضات!$B$4) | L32: =IF(G32=0,"",K32/G32-1) | M32: =IFERROR(VLOOKUP(A32,التوقعات!$A$4:$I$41,9,FALSE),0) | N32: =IF(M32=0,"",K32/M32)
A33: 11452109 | B33: اعتماد مخططات التطوير العقاري | C33: الرسوم والتراخيص | D33: =IF(AND(100.0=0,100.0=0),"متوقف","نشط") | E33: 536299.94 | F33: 1217856.2 | G33: 591946.73 | H33: 100 | I33: 0 | J33: 100 | K33: =IF(D33="متوقف",0,H33*الافتراضات!$B$4) | L33: =IF(G33=0,"",K33/G33-1) | M33: =IFERROR(VLOOKUP(A33,التوقعات!$A$4:$I$41,9,FALSE),0) | N33: =IF(M33=0,"",K33/M33)
A34: 11452107 | B34: اصدار التراخيص بتأسيس أو تشغيل الصراف الآلي | C34: الرسوم والتراخيص | D34: =IF(AND(200184.61=0,158934.61=0),"متوقف","نشط") | E34: 54000 | F34: 90000 | G34: 229800 | H34: 158934.61 | I34: 152461.09 | J34: 6473.52 | K34: =IF(D34="متوقف",0,H34*الافتراضات!$B$4) | L34: =IF(G34=0,"",K34/G34-1) | M34: =IFERROR(VLOOKUP(A34,التوقعات!$A$4:$I$41,9,FALSE),0) | N34: =IF(M34=0,"",K34/M34)
A35: 3318212 | B35: مرتجع رواتب - فواتير | C35: أخرى | D35: =IF(AND(361665.23=0,216725.66=0),"متوقف","نشط") | E35: 0 | F35: 0 | G35: 152767.79 | H35: 216725.66 | I35: 216725.66 | J35: 0 | K35: =IF(D35="متوقف",0,H35*الافتراضات!$B$4) | L35: =IF(G35=0,"",K35/G35-1) | M35: =IFERROR(VLOOKUP(A35,التوقعات!$A$4:$I$41,9,FALSE),0) | N35: =IF(M35=0,"",K35/M35)
A36: 11422 | B36: رسوم منتجات التبغ | C36: التبغ والإيواء | D36: =IF(AND(0.0=0,0.0=0),"متوقف","نشط") | E36: 27000 | F36: 5167 | G36: 27000 | H36: 0 | I36: 0 | J36: 0 | K36: =IF(D36="متوقف",0,H36*الافتراضات!$B$4) | L36: =IF(G36=0,"",K36/G36-1) | M36: =IFERROR(VLOOKUP(A36,التوقعات!$A$4:$I$41,9,FALSE),0) | N36: =IF(M36=0,"",K36/M36)
A37: 1422103 | B37: تراخيص المحلات | C37: إيرادات إستثمارية | D37: =IF(AND(432.0=0,432.0=0),"متوقف","نشط") | E37: 67711.6 | F37: 16269.6 | G37: 1603.2 | H37: 432 | I37: 0 | J37: 432 | K37: =IF(D37="متوقف",0,H37*الافتراضات!$B$4) | L37: =IF(G37=0,"",K37/G37-1) | M37: =IFERROR(VLOOKUP(A37,التوقعات!$A$4:$I$41,9,FALSE),0) | N37: =IF(M37=0,"",K37/M37)
A38: 11452513 | B38: لوحات إرشـادية | C38: الرسوم والتراخيص | D38: =IF(AND(600.0=0,600.0=0),"متوقف","نشط") | E38: 55525 | F38: 12875 | G38: 9000 | H38: 600 | I38: 0 | J38: 600 | K38: =IF(D38="متوقف",0,H38*الافتراضات!$B$4) | L38: =IF(G38=0,"",K38/G38-1) | M38: =IFERROR(VLOOKUP(A38,التوقعات!$A$4:$I$41,9,FALSE),0) | N38: =IF(M38=0,"",K38/M38)
A39: 1421907 | B39: إيرادات المخططات | C39: الرسوم والتراخيص | D39: =IF(AND(6350.0=0,5550.0=0),"متوقف","نشط") | E39: 0 | F39: 0 | G39: 20650 | H39: 5550 | I39: 5450 | J39: 100 | K39: =IF(D39="متوقف",0,H39*الافتراضات!$B$4) | L39: =IF(G39=0,"",K39/G39-1) | M39: =IFERROR(VLOOKUP(A39,التوقعات!$A$4:$I$41,9,FALSE),0) | N39: =IF(M39=0,"",K39/M39)
A40: 1421908 | B40: ايرادات رسوم خدمات بلدية | C40: إيرادات إستثمارية | D40: =IF(AND(0.0=0,0.0=0),"متوقف","نشط") | E40: 16385 | F40: 0 | G40: 0 | H40: 0 | I40: 0 | J40: 0 | K40: =IF(D40="متوقف",0,H40*الافتراضات!$B$4) | L40: =IF(G40=0,"",K40/G40-1) | M40: =IFERROR(VLOOKUP(A40,التوقعات!$A$4:$I$41,9,FALSE),0) | N40: =IF(M40=0,"",K40/M40)
...

Sheet تحليل التوقع والأسوأ
A1: لماذا هذا التوقع؟ تحليل كل حساب والسيناريو الأسوأ لإقفال 2026 (محصّل)
A2: التوقع الأساسي = المحصل حتى سبتمبر × 12÷9. السيناريو الأسوأ لكل حساب = الأكبر بين (المحصل حتى سبتمبر) و(الأصغر بين التوقع الأساسي ومحصل 2025)، أي: لا نمو عن 2025، والقفزات لا تتكرر، ولا ينزل الحساب عما حُصّل فعلاً. الحد الأدنى المطلق = المحصل حتى سبتمبر بدون أي تحصيل في الربع الأخير. نص السبب ثابت بحسب الافتراضات الحالية.
A3: الملخص: | C3: التوقع الأساسي | D3: =J43 | E3: السيناريو الأسوأ | F3: =K43 | G3: الحد الأدنى المطلق | H3: =G43 | I3: محصل 2025 | J3: =F43
A4: رقم الحساب | B4: اسم الحساب | C4: التبويب | D4: 2023 محصّل | E4: 2024 محصّل | F4: 2025 محصّل | G4: 2026 حتى سبتمبر | H4: حتى سبتمبر ÷ 2025 | I4: تحصيل الربع الأخير المتوقع | J4: التوقع الأساسي | K4: السيناريو الأسوأ | L4: الفرق (أسوأ − أساسي) | M4: حصة الحساب من الأساسي | N4: مستوى الخطر | O4: سبب التوقع
A5: 1438001 | B5: جزاءات و غرامات مفروضة بموجب أنظمة الجهة | C5: جزاءات وغرامات | D5: ='توقع المحصل 2026'!E4 | E5: ='توقع المحصل 2026'!F4 | F5: ='توقع المحصل 2026'!G4 | G5: ='توقع المحصل 2026'!H4 | H5: =IF(F5=0,"",G5/F5) | I5: =J5-G5 | J5: ='توقع المحصل 2026'!K4 | K5: =IF(J5=0,0,MAX(G5,MIN(J5,F5))) | L5: =K5-J5 | M5: =J5/J$43 | N5: مرتفع | O5: قفزة: المحصل حتى سبتمبر (370.6م) يعادل 120% من كل 2025 (308.0م)، والتوقع يفترض أن القفزة تستمر في الربع الأخير. احتمال المبالغة مرتفع.
A6: 14155 | B6: ريع الأراضي (تأجير الأراض ) | C6: إيرادات إستثمارية | D6: ='توقع المحصل 2026'!E5 | E6: ='توقع المحصل 2026'!F5 | F6: ='توقع المحصل 2026'!G5 | G6: ='توقع المحصل 2026'!H5 | H6: =IF(F6=0,"",G6/F6) | I6: =J6-G6 | J6: ='توقع المحصل 2026'!K5 | K6: =IF(J6=0,0,MAX(G6,MIN(J6,F6))) | L6: =K6-J6 | M6: =J6/J$43 | N6: مرتفع | O6: المحصل حتى سبتمبر (612.9م) بلغ 94% من كل 2025 (649.3م). إضافة الربع الأخير بنفس الوتيرة ترفع التوقع 26% فوق 2025، وإن كان التحصيل يتركز في بداية السنة فالتوقع مبالغ فيه.
A7: 142113 | B7: ايرادات اللوحات الدعائية | C7: الرسوم والتراخيص | D7: ='توقع المحصل 2026'!E6 | E7: ='توقع المحصل 2026'!F6 | F7: ='توقع المحصل 2026'!G6 | G7: ='توقع المحصل 2026'!H6 | H7: =IF(F7=0,"",G7/F7) | I7: =J7-G7 | J7: ='توقع المحصل 2026'!K6 | K7: =IF(J7=0,0,MAX(G7,MIN(J7,F7))) | L7: =K7-J7 | M7: =J7/J$43 | N7: مرتفع | O7: قفزة: المحصل حتى سبتمبر (122.0م) يعادل 118% من كل 2025 (103.6م)، والتوقع يفترض أن القفزة تستمر في الربع الأخير. احتمال المبالغة مرتفع.
A8: 11452104 | B8: إصدار رخص الأنشطة التجارية | C8: الرسوم والتراخيص | D8: ='توقع المحصل 2026'!E7 | E8: ='توقع المحصل 2026'!F7 | F8: ='توقع المحصل 2026'!G7 | G8: ='توقع المحصل 2026'!H7 | H8: =IF(F8=0,"",G8/F8) | I8: =J8-G8 | J8: ='توقع المحصل 2026'!K7 | K8: =IF(J8=0,0,MAX(G8,MIN(J8,F8))) | L8: =K8-J8 | M8: =J8/J$43 | N8: مرتفع | O8: المحصل حتى سبتمبر (250.4م) بلغ 94% من كل 2025 (267.5م). إضافة الربع الأخير بنفس الوتيرة ترفع التوقع 25% فوق 2025، وإن كان التحصيل يتركز في بداية السنة فالتوقع مبالغ فيه.
A9: 11452103 | B9: ايراد اصدار تراخيص المباني والاسوار - أمانة منطقة الرياض | C9: الرسوم والتراخيص | D9: ='توقع المحصل 2026'!E8 | E9: ='توقع المحصل 2026'!F8 | F9: ='توقع المحصل 2026'!G8 | G9: ='توقع المحصل 2026'!H8 | H9: =IF(F9=0,"",G9/F9) | I9: =J9-G9 | J9: ='توقع المحصل 2026'!K8 | K9: =IF(J9=0,0,MAX(G9,MIN(J9,F9))) | L9: =K9-J9 | M9: =J9/J$43 | N9: منخفض | O9: مستقر: التوقع (272.0م) قريب من محصل 2025 (319.7م).
A10: 11452512 | B10: ايرادات لوحات المحلات | C10: الرسوم والتراخيص | D10: ='توقع المحصل 2026'!E9 | E10: ='توقع المحصل 2026'!F9 | F10: ='توقع المحصل 2026'!G9 | G10: ='توقع المحصل 2026'!H9 | H10: =IF(F10=0,"",G10/F10) | I10: =J10-G10 | J10: ='توقع المحصل 2026'!K9 | K10: =IF(J10=0,0,MAX(G10,MIN(J10,F10))) | L10: =K10-J10 | M10: =J10/J$43 | N10: متوسط | O10: التوقع أعلى من 2025 بنسبة 20% لأن وتيرة التحصيل حتى سبتمبر أعلى.
A11: 11442 | B11: اشغال مرافق الايواء | C11: التبغ والإيواء | D11: ='توقع المحصل 2026'!E10 | E11: ='توقع المحصل 2026'!F10 | F11: ='توقع المحصل 2026'!G10 | G11: ='توقع المحصل 2026'!H10 | H11: =IF(F11=0,"",G11/F11) | I11: =J11-G11 | J11: ='توقع المحصل 2026'!K10 | K11: =IF(J11=0,0,MAX(G11,MIN(J11,F11))) | L11: =K11-J11 | M11: =J11/J$43 | N11: منخفض | O11: مستقر: التوقع (182.2م) قريب من محصل 2025 (199.1م).
A12: 142162 | B12: إيرادات تأجير المرافق | C12: إيرادات إستثمارية | D12: ='توقع المحصل 2026'!E11 | E12: ='توقع المحصل 2026'!F11 | F12: ='توقع المحصل 2026'!G11 | G12: ='توقع المحصل 2026'!H11 | H12: =IF(F12=0,"",G12/F12) | I12: =J12-G12 | J12: ='توقع المحصل 2026'!K11 | K12: =IF(J12=0,0,MAX(G12,MIN(J12,F12))) | L12: =K12-J12 | M12: =J12/J$43 | N12: منخفض | O12: التوقع أدنى من 2025 بنسبة 39% لأن وتيرة التحصيل حتى سبتمبر أقل.
A13: 1421999 | B13: مبيعات أخرى | C13: أخرى | D13: ='توقع المحصل 2026'!E12 | E13: ='توقع المحصل 2026'!F12 | F13: ='توقع المحصل 2026'!G12 | G13: ='توقع المحصل 2026'!H12 | H13: =IF(F13=0,"",G13/F13) | I13: =J13-G13 | J13: ='توقع المحصل 2026'!K12 | K13: =IF(J13=0,0,MAX(G13,MIN(J13,F13))) | L13: =K13-J13 | M13: =J13/J$43 | N13: مرتفع | O13: قفزة: المحصل حتى سبتمبر (134.1م) يعادل 223% من كل 2025 (60.1م)، والتوقع يفترض أن القفزة تستمر في الربع الأخير. احتمال المبالغة مرتفع.
A14: 144122 | B14: إيرادات متنوعه | C14: أخرى | D14: ='توقع المحصل 2026'!E13 | E14: ='توقع المحصل 2026'!F13 | F14: ='توقع المحصل 2026'!G13 | G14: ='توقع المحصل 2026'!H13 | H14: =IF(F14=0,"",G14/F14) | I14: =J14-G14 | J14: ='توقع المحصل 2026'!K13 | K14: =IF(J14=0,0,MAX(G14,MIN(J14,F14))) | L14: =K14-J14 | M14: =J14/J$43 | N14: مرتفع | O14: قفزة: المحصل حتى سبتمبر (20.8م) يعادل 840% من كل 2025 (2.5م)، والتوقع يفترض أن القفزة تستمر في الربع الأخير. احتمال المبالغة مرتفع.
A15: 1421911 | B15: رسم مبيعات محلات تقديم منتجات التبغ | C15: التبغ والإيواء | D15: ='توقع المحصل 2026'!E14 | E15: ='توقع المحصل 2026'!F14 | F15: ='توقع المحصل 2026'!G14 | G15: ='توقع المحصل 2026'!H14 | H15: =IF(F15=0,"",G15/F15) | I15: =J15-G15 | J15: ='توقع المحصل 2026'!K14 | K15: =IF(J15=0,0,MAX(G15,MIN(J15,F15))) | L15: =K15-J15 | M15: =J15/J$43 | N15: منخفض | O15: مستقر: التوقع (75.6م) قريب من محصل 2025 (67.6م).
A16: 1421909 | B16: جمع النفايات | C16: الرسوم والتراخيص | D16: ='توقع المحصل 2026'!E15 | E16: ='توقع المحصل 2026'!F15 | F16: ='توقع المحصل 2026'!G15 | G16: ='توقع المحصل 2026'!H15 | H16: =IF(F16=0,"",G16/F16) | I16: =J16-G16 | J16: ='توقع المحصل 2026'!K15 | K16: =IF(J16=0,0,MAX(G16,MIN(J16,F16))) | L16: =K16-J16 | M16: =J16/J$43 | N16: مرتفع | O16: المحصل حتى سبتمبر (72.2م) بلغ 99% من كل 2025 (72.8م). إضافة الربع الأخير بنفس الوتيرة ترفع التوقع 32% فوق 2025، وإن كان التحصيل يتركز في بداية السنة فالتوقع مبالغ فيه.
... A42: 142161 | B42: تاجير مباني سكنية | C42: إيرادات إستثمارية | D42: ='توقع المحصل 2026'!E41 | E42: ='توقع المحصل 2026'!F41 | F42: ='توقع المحصل 2026'!G41 | G42: ='توقع المحصل 2026'!H41 | H42: =IF(F42=0,"",G42/F42) | I42: =J42-G42 | J42: ='توقع المحصل 2026'!K41 | K42: =IF(J42=0,0,MAX(G42,MIN(J42,F42))) | L42: =K42-J42 | M42: =J42/J$43 | N42: منخفض | O42: متوقف: لا فوترة ولا تحصيل في 2026، فتوقعه صفر.
B43: الإجمالي | D43: =SUM(D5:D42) | E43: =SUM(E5:E42) | F43: =SUM(F5:F42) | G43: =SUM(G5:G42) | H43: =G43/F43 | I43: =SUM(I5:I42) | J43: =SUM(J5:J42) | K43: =SUM(K5:K42) | L43: =SUM(L5:L42) | M43: =SUM(M5:M42)

Sheet توقع المحصل الموسمي
A1: توقع إقفال 2026 (محصّل) بالموسمية الشهرية — بدون الضريبة
A2: الطريقة: توقع الربع الأخير (أكتوبر–ديسمبر) = وسيط تحصيل الربع الأخير في 2023–2025 × معامل الاتجاه، ومعامل الاتجاه = المحصل يناير–سبتمبر 2026 ÷ وسيط يناير–سبتمبر للسنوات الثلاث، بين حدّين في ورقة الافتراضات. الإقفال = المحصل يناير–سبتمبر + توقع الربع الأخير. السيناريو الأسوأ: الربع الأخير = أدنى ربع أخير في السنوات الثلاث × (معامل الاتجاه بحد أقصى 1). في الحالتين لا يقل الربع الأخير عن المحصل الفعلي من أكتوبر حتى تاريخ الملف. الوسيط يخفف أثر الشهور الاستثنائية.
A3: الملخص: | C3: إقفال 2026 – أساسي | D3: =M44 | E3: إقفال 2026 – أسوأ | F3: =N44 | G3: الحد الأدنى (يناير–سبتمبر + أكتوبر حتى تاريخه) | H3: =E44+F44 | I3: محصل 2025 | J3: =D44
A5: رقم الحساب | B5: اسم الحساب | C5: التبويب | D5: 2025 محصّل (سنة كاملة) | E5: 2026 محصّل يناير–سبتمبر | F5: 2026 محصّل أكتوبر حتى تاريخه | G5: وسيط يناير–سبتمبر 2023–2025 | H5: وسيط الربع الأخير 2023–2025 | I5: أدنى ربع أخير 2023–2025 | J5: معامل الاتجاه | K5: الربع الأخير – أساسي | L5: الربع الأخير – أسوأ | M5: إقفال 2026 – أساسي | N5: إقفال 2026 – أسوأ | O5: الطريقة البسيطة (×12÷9) | P5: الفرق: أساسي − بسيط | Q5: نمو الأساسي عن 2025
A6: 14155 | B6: ريع الأراضي (تأجير الأراض ) | C6: إيرادات إستثمارية | D6: 6.4933179e+08 | E6: 6.119231e+08 | F6: 966021.95 | G6: 4.6928881e+08 | H6: 2.2890745e+08 | I6: 2.0433314e+08 | J6: =IF(G6>0,MIN(الافتراضات!$B$8,MAX(الافتراضات!$B$7,E6/G6)),IF(E6>0,1,0)) | K6: =IF(AND(E6=0,F6=0),0,MAX(F6,H6*J6)) | L6: =IF(AND(E6=0,F6=0),0,MAX(F6,I6*MIN(J6,1))) | M6: =E6+K6 | N6: =E6+L6 | O6: =E6*12/9 | P6: =M6-O6 | Q6: =IF(D6=0,"",M6/D6-1)
A7: 1438001 | B7: جزاءات و غرامات مفروضة بموجب أنظمة الجهة | C7: جزاءات وغرامات | D7: 3.080122e+08 | E7: 3.7011648e+08 | F7: 495850 | G7: 2.3845058e+08 | H7: 85816587 | I7: 65135107 | J7: =IF(G7>0,MIN(الافتراضات!$B$8,MAX(الافتراضات!$B$7,E7/G7)),IF(E7>0,1,0)) | K7: =IF(AND(E7=0,F7=0),0,MAX(F7,H7*J7)) | L7: =IF(AND(E7=0,F7=0),0,MAX(F7,I7*MIN(J7,1))) | M7: =E7+K7 | N7: =E7+L7 | O7: =E7*12/9 | P7: =M7-O7 | Q7: =IF(D7=0,"",M7/D7-1)
A8: 142162 | B8: إيرادات تأجير المرافق | C8: إيرادات إستثمارية | D8: 9.3888968e+08 | E8: 4.2845406e+08 | F8: 5982.8 | G8: 29251064 | H8: 32592532 | I8: 322650 | J8: =IF(G8>0,MIN(الافتراضات!$B$8,MAX(الافتراضات!$B$7,E8/G8)),IF(E8>0,1,0)) | K8: =IF(AND(E8=0,F8=0),0,MAX(F8,H8*J8)) | L8: =IF(AND(E8=0,F8=0),0,MAX(F8,I8*MIN(J8,1))) | M8: =E8+K8 | N8: =E8+L8 | O8: =E8*12/9 | P8: =M8-O8 | Q8: =IF(D8=0,"",M8/D8-1)
A9: 11452104 | B9: إصدار رخص الأنشطة التجارية | C9: الرسوم والتراخيص | D9: 2.6749628e+08 | E9: 2.4751532e+08 | F9: 2860329 | G9: 1.9561929e+08 | H9: 70733181 | I9: 70219228 | J9: =IF(G9>0,MIN(الافتراضات!$B$8,MAX(الافتراضات!$B$7,E9/G9)),IF(E9>0,1,0)) | K9: =IF(AND(E9=0,F9=0),0,MAX(F9,H9*J9)) | L9: =IF(AND(E9=0,F9=0),0,MAX(F9,I9*MIN(J9,1))) | M9: =E9+K9 | N9: =E9+L9 | O9: =E9*12/9 | P9: =M9-O9 | Q9: =IF(D9=0,"",M9/D9-1)
A10: 11452103 | B10: ايراد اصدار تراخيص المباني والاسوار - أمانة منطقة الرياض | C10: الرسوم والتراخيص | D10: 3.1967527e+08 | E10: 2.0393835e+08 | F10: 64468.55 | G10: 1.7162442e+08 | H10: 72958069 | I10: 56149701 | J10: =IF(G10>0,MIN(الافتراضات!$B$8,MAX(الافتراضات!$B$7,E10/G10)),IF(E10>0,1,0)) | K10: =IF(AND(E10=0,F10=0),0,MAX(F10,H10*J10)) | L10: =IF(AND(E10=0,F10=0),0,MAX(F10,I10*MIN(J10,1))) | M10: =E10+K10 | N10: =E10+L10 | O10: =E10*12/9 | P10: =M10-O10 | Q10: =IF(D10=0,"",M10/D10-1)
A11: 11452512 | B11: ايرادات لوحات المحلات | C11: الرسوم والتراخيص | D11: 1.9383078e+08 | E11: 1.7196152e+08 | F11: 2332984.9 | G11: 155986575 | H11: 59354580 | I11: 51365276 | J11: =IF(G11>0,MIN(الافتراضات!$B$8,MAX(الافتراضات!$B$7,E11/G11)),IF(E11>0,1,0)) | K11: =IF(AND(E11=0,F11=0),0,MAX(F11,H11*J11)) | L11: =IF(AND(E11=0,F11=0),0,MAX(F11,I11*MIN(J11,1))) | M11: =E11+K11 | N11: =E11+L11 | O11: =E11*12/9 | P11: =M11-O11 | Q11: =IF(D11=0,"",M11/D11-1)
A12: 11442 | B12: اشغال مرافق الايواء | C12: التبغ والإيواء | D12: 1.9914967e+08 | E12: 1.3582427e+08 | F12: 815494.87 | G12: 1.5296834e+08 | H12: 66937520 | I12: 57302452 | J12: =IF(G12>0,MIN(الافتراضات!$B$8,MAX(الافتراضات!$B$7,E12/G12)),IF(E12>0,1,0)) | K12: =IF(AND(E12=0,F12=0),0,MAX(F12,H12*J12)) | L12: =IF(AND(E12=0,F12=0),0,MAX(F12,I12*MIN(J12,1))) | M12: =E12+K12 | N12: =E12+L12 | O12: =E12*12/9 | P12: =M12-O12 | Q12: =IF(D12=0,"",M12/D12-1)
A13: 1421999 | B13: مبيعات أخرى | C13: أخرى | D13: 60096374 | E13: 1.3407643e+08 | F13: 0 | G13: 78879723 | H13: 19648594 | I13: 5322376.9 | J13: =IF(G13>0,MIN(الافتراضات!$B$8,MAX(الافتراضات!$B$7,E13/G13)),IF(E13>0,1,0)) | K13: =IF(AND(E13=0,F13=0),0,MAX(F13,H13*J13)) | L13: =IF(AND(E13=0,F13=0),0,MAX(F13,I13*MIN(J13,1))) | M13: =E13+K13 | N13: =E13+L13 | O13: =E13*12/9 | P13: =M13-O13 | Q13: =IF(D13=0,"",M13/D13-1)
A14: 142113 | B14: ايرادات اللوحات الدعائية | C14: الرسوم والتراخيص | D14: 1.0358998e+08 | E14: 1.2170439e+08 | F14: 327373.48 | G14: 1.2279736e+08 | H14: 35149182 | I14: 18399321 | J14: =IF(G14>0,MIN(الافتراضات!$B$8,MAX(الافتراضات!$B$7,E14/G14)),IF(E14>0,1,0)) | K14: =IF(AND(E14=0,F14=0),0,MAX(F14,H14*J14)) | L14: =IF(AND(E14=0,F14=0),0,MAX(F14,I14*MIN(J14,1))) | M14: =E14+K14 | N14: =E14+L14 | O14: =E14*12/9 | P14: =M14-O14 | Q14: =IF(D14=0,"",M14/D14-1)
A15: 1421909 | B15: جمع النفايات | C15: الرسوم والتراخيص | D15: 72842924 | E15: 71391993 | F15: 831524.83 | G15: 53175299 | H15: 20735772 | I15: 18851086 | J15: =IF(G15>0,MIN(الافتراضات!$B$8,MAX(الافتراضات!$B$7,E15/G15)),IF(E15>0,1,0)) | K15: =IF(AND(E15=0,F15=0),0,MAX(F15,H15*J15)) | L15: =IF(AND(E15=0,F15=0),0,MAX(F15,I15*MIN(J15,1))) | M15: =E15+K15 | N15: =E15+L15 | O15: =E15*12/9 | P15: =M15-O15 | Q15: =IF(D15=0,"",M15/D15-1)
A16: 1421911 | B16: رسم مبيعات محلات تقديم منتجات التبغ | C16: التبغ والإيواء | D16: 67630101 | E16: 56321815 | F16: 349894.61 | G16: 52213519 | H16: 19979809 | I16: 15416582 | J16: =IF(G16>0,MIN(الافتراضات!$B$8,MAX(الافتراضات!$B$7,E16/G16)),IF(E16>0,1,0)) | K16: =IF(AND(E16=0,F16=0),0,MAX(F16,H16*J16)) | L16: =IF(AND(E16=0,F16=0),0,MAX(F16,I16*MIN(J16,1))) | M16: =E16+K16 | N16: =E16+L16 | O16: =E16*12/9 | P16: =M16-O16 | Q16: =IF(D16=0,"",M16/D16-1)
A17: 11452108 | B17: ايراد اصدار القرارات المساحية - أمانة منطقة الرياض | C17: الرسوم والتراخيص | D17: 24531494 | E17: 30875270 | F17: 303578.42 | G17: 13801002 | H17: 5538696 | I17: 1955277.9 | J17: =IF(G17>0,MIN(الافتراضات!$B$8,MAX(الافتراضات!$B$7,E17/G17)),IF(E17>0,1,0)) | K17: =IF(AND(E17=0,F17=0),0,MAX(F17,H17*J17)) | L17: =IF(AND(E17=0,F17=0),0,MAX(F17,I17*MIN(J17,1))) | M17: =E17+K17 | N17: =E17+L17 | O17: =E17*12/9 | P17: =M17-O17 | Q17: =IF(D17=0,"",M17/D17-1)
... A43: 1421908 | B43: ايرادات رسوم خدمات بلدية | C43: إيرادات إستثمارية | D43: 0 | E43: 0 | F43: 0 | G43: 0 | H43: 0 | I43: 0 | J43: =IF(G43>0,MIN(الافتراضات!$B$8,MAX(الافتراضات!$B$7,E43/G43)),IF(E43>0,1,0)) | K43: =IF(AND(E43=0,F43=0),0,MAX(F43,H43*J43)) | L43: =IF(AND(E43=0,F43=0),0,MAX(F43,I43*MIN(J43,1))) | M43: =E43+K43 | N43: =E43+L43 | O43: =E43*12/9 | P43: =M43-O43 | Q43: =IF(D43=0,"",M43/D43-1)
B44: الإجمالي | D44: =SUM(D6:D43) | E44: =SUM(E6:E43) | F44: =SUM(F6:F43) | G44: =SUM(G6:G43) | H44: =SUM(H6:H43) | I44: =SUM(I6:I43) | K44: =SUM(K6:K43) | L44: =SUM(L6:L43) | M44: =SUM(M6:M43) | N44: =SUM(N6:N43) | O44: =SUM(O6:O43) | P44: =SUM(P6:P43) | Q44: =M44/D44-1

Sheet الموسمية الشهرية
A1: المحصل الشهري الإجمالي (بدون الضريبة) وحصة كل شهر من السنة
A2: 2026: أكتوبر جزئي (حتى تاريخ الملف) ونوفمبر وديسمبر لم يحصلا بعد. بعد إعادة التصنيف: نقل 913م من حساب اللوحات الدعائية (142113) إلى تأجير المرافق (142162) في 2025 (مايو 291م ونوفمبر 594م، من إدارة الدعم المالي) حسب تأكيد المستخدم. شهور الذروة المتبقية: يوليو 2024 (312م، إدارة الدعم المالي، لم تُنقل)، يونيو 2026 (تأجير المرافق 409م).
A4: السنة | B4: يناير | C4: فبراير | D4: مارس | E4: أبريل | F4: مايو | G4: يونيو | H4: يوليو | I4: أغسطس | J4: سبتمبر | K4: أكتوبر | L4: نوفمبر | M4: ديسمبر | N4: الإجمالي | O4: حتى سبتمبر % | P4: الربع الأخير %
A5: 2023 | B5: 2.4271887e+08 | C5: 1.9022638e+08 | D5: 2.1369346e+08 | E5: 1.3749618e+08 | F5: 2.6678105e+08 | G5: 1.8898072e+08 | H5: 2.5811056e+08 | I5: 2.4522266e+08 | J5: 2.9262659e+08 | K5: 2.7631747e+08 | L5: 2.0897381e+08 | M5: 2.3758312e+08 | N5: =SUM(B5:M5) | O5: =SUM(B5:J5)/N5 | P5: =SUM(K5:M5)/N5
A6: 2024 | B6: 2.636099e+08 | C6: 2.2583785e+08 | D6: 1.6712529e+08 | E6: 1.4004128e+08 | F6: 224669391 | G6: 2.0645112e+08 | H6: 5.3748496e+08 | I6: 2.1914776e+08 | J6: 2.1377851e+08 | K6: 3.3943692e+08 | L6: 2.9204347e+08 | M6: 3.6308183e+08 | N6: =SUM(B6:M6) | O6: =SUM(B6:J6)/N6 | P6: =SUM(K6:M6)/N6
A7: 2025 | B7: 2.4462904e+08 | C7: 1.9916033e+08 | D7: 1.7462713e+08 | E7: 1.4077705e+08 | F7: 4.8459323e+08 | G7: 1.7463822e+08 | H7: 2.2055265e+08 | I7: 1.780589e+08 | J7: 2.066135e+08 | K7: 2.0104713e+08 | L7: 8.4272697e+08 | M7: 2.421195e+08 | N7: =SUM(B7:M7) | O7: =SUM(B7:J7)/N7 | P7: =SUM(K7:M7)/N7
A8: 2026 | B8: 2.2926254e+08 | C8: 2.776226e+08 | D8: 1.6630595e+08 | E8: 2.6328978e+08 | F8: 2.5184702e+08 | G8: 7.1212584e+08 | H8: 2.7174682e+08 | I8: 2.5693048e+08 | J8: 2.4436387e+08 | K8: 10145046 | N8: =SUM(B8:M8)
A10: حصة الشهر من السنة % | B10: يناير | C10: فبراير | D10: مارس | E10: أبريل | F10: مايو | G10: يونيو | H10: يوليو | I10: أغسطس | J10: سبتمبر | K10: أكتوبر | L10: نوفمبر | M10: ديسمبر
A11: 2023 | B11: =B5/$N5 | C11: =C5/$N5 | D11: =D5/$N5 | E11: =E5/$N5 | F11: =F5/$N5 | G11: =G5/$N5 | H11: =H5/$N5 | I11: =I5/$N5 | ... M11: =M5/$N5
A12: 2024 | B12: =B6/$N6 | C12: =C6/$N6 | D12: =D6/$N6 | E12: =E6/$N6 | F12: =F6/$N6 | G12: =G6/$N6 | H12: =H6/$N6 | I12: =I6/$N6 | ... M12: =M6/$N6
A13: 2025 | B13: =B7/$N7 | C13: =C7/$N7 | D13: =D7/$N7 | E13: =E7/$N7 | F13: =F7/$N7 | G13: =G7/$N7 | H13: =H7/$N7 | I13: =I7/$N7 | ... M13: =M7/$N7

Sheet توقع المحصل (المراقبة)
A1: توقع إقفال 2026 (محصّل) بعد اعتماد إجمالي يناير–أكتوبر من ملف المراقبة
A2: المحصل الفعلي يناير–أكتوبر 2026 = ورقة "الإجمالي" في ملف المراقبة (قبل الاستقطاع = بعد الاستقطاع + التوريد + المستقطع)، وأكتوبر جزئي حتى تاريخ الملف. الإقفال الأساسي = الفعلي + المتبقي من أكتوبر + نوفمبر وديسمبر؛ المتبقي من أكتوبر = المتوسط الموسمي لأكتوبر × معامل الاتجاه − المحصل حتى تاريخه (لا يقل عن صفر)؛ نوفمبر وديسمبر = وسيط 2023–2025 × معامل الاتجاه. السيناريو الأسوأ: أدنى قيمة تاريخية بدل الوسيط × (الاتجاه بحد أقصى 1). الحسابات التي في ملف المراقبة فقط ولا تاريخ لها في الملف الشهري (1431 و1422104 و1422112 و1422199 و1422202) تُبقى على الفعلي بدون إضافة. بنود التوريد (شيك/تحويل/تنفيذ) داخلة في الفعلي لكن لا تُتوقع للأشهر المتبقية لأنها غير منتظمة، فهي خطر صعودي.
A3: الملخص: | C3: الفعلي يناير–أكتوبر (المراقبة) | D3: =D49 | E3: إقفال 2026 – أساسي | F3: =M49 | G3: إقفال 2026 – أسوأ | H3: =P49 | I3: المقدر 2026 (المراقبة) | J3: =Q49 | K3: المستهدف 2026 | L3: =R49
A5: رقم الحساب | B5: اسم الحساب | C5: التبويب | D5: الفعلي يناير–أكتوبر (المراقبة) | E5: منه: أكتوبر حتى تاريخه | F5: وسيط أكتوبر 2023–2025 | G5: وسيط نوفمبر+ديسمبر 2023–2025 | H5: أدنى أكتوبر | I5: أدنى نوفمبر+ديسمبر | J5: معامل الاتجاه | K5: متبقي أكتوبر – أساسي | L5: نوفمبر+ديسمبر – أساسي | M5: إقفال 2026 – أساسي | N5: متبقي أكتوبر – أسوأ | O5: نوفمبر+ديسمبر – أسوأ | P5: إقفال 2026 – أسوأ | Q5: المقدر 2026 (المراقبة) | R5: المستهدف 2026 (المراقبة) | S5: الأساسي − المقدر | T5: الأساسي ÷ المستهدف | U5: مصدر الفعلي
A6: 14155 | B6: ريع الأراضي (تأجير الأراض ) | C6: إيرادات إستثمارية | D6: 6.4448716e+08 | E6: 32158748 | F6: 1.0986008e+08 | G6: 1.600487e+08 | H6: 44284438 | I6: 1.1904737e+08 | J6: =IFERROR(VLOOKUP(A6,'توقع المحصل الموسمي'!$A$6:$J$43,10,FALSE),1) | K6: =MAX(0,F6*J6-E6) | L6: =G6*J6 | M6: =D6+K6+L6 | N6: =MAX(0,H6*MIN(J6,1)-E6) | O6: =I6*MIN(J6,1) | P6: =D6+N6+O6 | Q6: 7.0420454e+08 | R6: 7.3689341e+08 | S6: =M6-Q6 | T6: =IF(R6=0,"",M6/R6) | U6: ملف المراقبة
A7: 142162 | B7: إيرادات تأجير المرافق | C7: إيرادات إستثمارية | D7: 4.2871499e+08 | E7: 322955.69 | F7: 524480.25 | G7: 32068052 | H7: 164700 | I7: 157950 | J7: =IFERROR(VLOOKUP(A7,'توقع المحصل الموسمي'!$A$6:$J$43,10,FALSE),1) | K7: =MAX(0,F7*J7-E7) | L7: =G7*J7 | M7: =D7+K7+L7 | N7: =MAX(0,H7*MIN(J7,1)-E7) | O7: =I7*MIN(J7,1) | P7: =D7+N7+O7 | Q7: 5.0288277e+08 | R7: 1.0032761e+09 | S7: =M7-Q7 | T7: =IF(R7=0,"",M7/R7) | U7: ملف المراقبة
A8: 1438001 | B8: جزاءات و غرامات مفروضة بموجب أنظمة الجهة | C8: جزاءات وغرامات | D8: 3.8969665e+08 | E8: 33304429 | F8: 29549276 | G8: 56267311 | H8: 16531183 | I8: 48603925 | J8: =IFERROR(VLOOKUP(A8,'توقع المحصل الموسمي'!$A$6:$J$43,10,FALSE),1) | K8: =MAX(0,F8*J8-E8) | L8: =G8*J8 | M8: =D8+K8+L8 | N8: =MAX(0,H8*MIN(J8,1)-E8) | O8: =I8*MIN(J8,1) | P8: =D8+N8+O8 | Q8: 4.1758722e+08 | R8: 4.4146374e+08 | S8: =M8-Q8 | T8: =IF(R8=0,"",M8/R8) | U8: ملف المراقبة
A9: 11452104 | B9: إصدار رخص الأنشطة التجارية | C9: الرسوم والتراخيص | D9: 2.6043588e+08 | E9: 13834961 | F9: 25241853 | G9: 46330432 | H9: 23888796 | I9: 45491328 | J9: =IFERROR(VLOOKUP(A9,'توقع المحصل الموسمي'!$A$6:$J$43,10,FALSE),1) | K9: =MAX(0,F9*J9-E9) | L9: =G9*J9 | M9: =D9+K9+L9 | N9: =MAX(0,H9*MIN(J9,1)-E9) | O9: =I9*MIN(J9,1) | P9: =D9+N9+O9 | Q9: 2.8473117e+08 | R9: 3.1591466e+08 | S9: =M9-Q9 | T9: =IF(R9=0,"",M9/R9) | U9: ملف المراقبة
A10: 11452103 | B10: ايراد اصدار تراخيص المباني والاسوار - أمانة منطقة الرياض | C10: الرسوم والتراخيص | D10: 2.1375869e+08 | E10: 10111053 | F10: 23653967 | G10: 49304102 | H10: 18226070 | I10: 37923631 | J10: =IFERROR(VLOOKUP(A10,'توقع المحصل الموسمي'!$A$6:$J$43,10,FALSE),1) | K10: =MAX(0,F10*J10-E10) | L10: =G10*J10 | M10: =D10+K10+L10 | N10: =MAX(0,H10*MIN(J10,1)-E10) | O10: =I10*MIN(J10,1) | P10: =D10+N10+O10 | Q10: 2.96615e+08 | R10: 3.1740442e+08 | S10: =M10-Q10 | T10: =IF(R10=0,"",M10/R10) | U10: ملف المراقبة
A11: 11452512 | B11: ايرادات لوحات المحلات | C11: الرسوم والتراخيص | D11: 1.8450881e+08 | E11: 10443753 | F11: 20956485 | G11: 38398095 | H11: 17387315 | I11: 33977961 | J11: =IFERROR(VLOOKUP(A11,'توقع المحصل الموسمي'!$A$6:$J$43,10,FALSE),1) | K11: =MAX(0,F11*J11-E11) | L11: =G11*J11 | M11: =D11+K11+L11 | N11: =MAX(0,H11*MIN(J11,1)-E11) | O11: =I11*MIN(J11,1) | P11: =D11+N11+O11 | Q11: 2.4765626e+08 | R11: 2.4823148e+08 | S11: =M11-Q11 | T11: =IF(R11=0,"",M11/R11) | U11: ملف المراقبة
